Workbook

Sheet 物料档案表
A1: 物料编码 | B1: 货物名称 | C1: 规格及材质 | D1: 单位 | E1: 适用成品 | F1: 物料大类 | G1: 是否通用 | H1: 安全库存 | I1: 备注说明
A2: CL-001 | B2: 0.3拉簧 | D2: 个 | E2: 牙线盒 | F2: 原材料 | G2: 否 | H2: 10000
A3: CL-002 | B3: 0.2压簧 | D3: 个 | E3: 牙线盒 | F3: 原材料 | G3: 否 | H3: 10000
A4: CL-003 | B4: 磁铁 | C4: D6*2 | D4: 片 | E4: A款,B款 | F4: 原材料 | G4: 是 | H4: 20000 | I4: 多成品通用物料
A5: CL-004 | B5: 磁铁 | C5: D6*3 | D5: 片 | E5: A款,B款 | F5: 原材料 | G5: 是 | H5: 10000 | I5: 多成品通用物料
A6: CL-005 | B6: 201 中轴 | C6: 10*0.4*340 | D6: pcs | E6: 340铝管,350铝轴 | F6: 原材料 | G6: 是 | H6: 2000 | I6: 多成品通用物料
A7: CL-006 | B7: 201 | C7: 10*0.4*350 | D7: pcs | E7: 350铝轴 | F7: 原材料 | G7: 否 | H7: 2000
A8: CL-007 | B8: EX 磁铁 | C8: 250*55*1.5 | D8: pcs | E8: E款 | F8: 原材料 | G8: 否 | H8: 1000
A9: CL-008 | B9: M款 磁铁 | C9: 249*60*2.0mm | D9: pcs | E9: M金属款 | F9: 原材料 | G9: 否 | H9: 500
A10: CL-009 | B10: 不锈钢外壳 | C10: 304 | D10: pcs | E10: M金属款 | F10: 原材料 | G10: 否 | H10: 500
A11: CL-010 | B11: SN 磁铁 | C11: 165*58*1.5mm | D11: pcs | E11: SN收纳盒 | F11: 原材料 | G11: 否 | H11: 500
A12: CL-011 | B12: B款 磁铁 | C12: 159*28*1.5mm | D12: pcs | E12: B款 | F12: 原材料 | G12: 否 | H12: 1000
A13: CL-012 | B13: B款 磁铁 | C13: 54.6*28*1.5mm | D13: pcs | E13: B款 | F13: 原材料 | G13: 否 | H13: 1000
A14: CL-013 | B14: 硅胶吸盘 | D14: 套 | E14: A款 | F14: 原材料 | G14: 否 | H14: 1000
A15: CL-014 | B15: CE100款 磁铁 | C15: 265*58.5*1.5mm | D15: pcs | E15: CE100款 | F15: 原材料 | G15: 否 | H15: 200
A16: CL-015 | B16: 条形磁铁 | C16: 323*24*1.5 | E16: A款 | F16: 原材料 | G16: 否 | H16: 500
A17: BZ-001 | B17: 子扣 | C17: 6*6CM | D17: 包 | E17: 通用,E款,M款 | F17: 包装辅料 | G17: 是 | H17: 10000 | I17: 多成品通用物料
A18: BZ-002 | B18: PVC导轨条 | C18: 330MM | D18: 根 | E18: 通用 | F18: 包装辅料 | G18: 否 | H18: 10000
A19: BZ-003 | B19: 磨砂袋 | C19: 牙线盒 | D19: 个 | E19: 牙线盒 | F19: 包装辅料 | G19: 否 | H19: 5000
A20: BZ-004 | B20: 气泡袋 | C20: 15*43CM | D20: 个 | E20: M金属款 | F20: 包装辅料 | G20: 否 | H20: 2000
A21: BZ-005 | B21: SN 磨砂袋 | C21: 14.5*29cm | D21: CPE | E21: SN收纳盒 | F21: 包装辅料 | G21: 否 | H21: 1000
A22: BZ-006 | B22: EX 磨砂袋 | C22: 14.5*49cm | D22: CPE | E22: E款,B款 | F22: 包装辅料 | G22: 是 | H22: 1000 | I22: 多成品通用物料
A23: BZ-007 | B23: E款 中文 | C23: 88*66*380mm | D23: 个 | E23: E款 | F23: 包装辅料 | G23: 否 | H23: 2000
A24: BZ-008 | B24: E款 英文 | C24: 88*66*380mm | D24: 个 | E24: E款 | F24: 包装辅料 | G24: 否 | H24: 2000
A25: BZ-009 | B25: CE32 外箱 | C25: 560*385*395mm | D25: 个 | E25: E款,B款 | F25: 包装辅料 | G25: 是 | H25: 500 | I25: 多成品通用物料
A26: BZ-010 | B26: H款快递盒 | C26: 222*105*410mm | D26: 个 | E26: 打包盒 | F26: 包装辅料 | G26: 否 | H26: 1000
A27: BZ-011 | B27: M+200M 纸盒 | C27: 124*100*395mm | D27: 个 | E27: 打包盒 | F27: 包装辅料 | G27: 否 | H27: 1000
A28: BZ-012 | B28: M款彩盒-中文 | D28: 个 | E28: M金属款 | F28: 包装辅料 | G28: 否 | H28: 500
A29: BZ-013 | B29: M款彩盒-英文 | D29: 个 | E29: M金属款 | F29: 包装辅料 | G29: 否 | H29: 500
A30: BZ-014 | B30: 子扣 | C30: 75C60*60方格 | D30: 片 | E30: SA收纳盒 | F30: 包装辅料 | G30: 否 | H30: 1000
A31: BZ-015 | B31: 子扣 | C31: 75C60*60方格（25mm) | D31: 包 | E31: SN收纳盒 | F31: 包装辅料 | G31: 否 | H31: 1000
A32: BZ-016 | B32: 保鲜膜 中文 | C32: 30CM*100M | D32: 箱 | E32: 保鲜膜 | F32: 包装辅料 | G32: 否 | H32: 100
A33: BZ-017 | B33: 保鲜膜 中文 | C33: 30CM*50M | D33: 箱 | E33: 保鲜膜 | F33: 包装辅料 | G33: 否 | H33: 100
A34: BZ-018 | B34: SA 磨砂袋 | C34: 220*290 | D34: CPE | E34: SA收纳盒 | F34: 包装辅料 | G34: 否 | H34: 500
A35: BZ-019 | B35: 纸箱12 | C35: 390*100*82mm | D35: 个 | E35: 打包盒 | F35: 包装辅料 | G35: 否 | H35: 500
A36: BZ-020 | B36: E100 说明书 | D36: 个 | E36: E款 | F36: 包装辅料 | G36: 否 | H36: 2000
A37: BZ-021 | B37: M20 外箱 | C37: 400*380*410 | D37: 个 | E37: M金属款 | F37: 包装辅料 | G37: 否 | H37: 300
A38: BZ-022 | B38: B款 英文纸盒 | C38: 88*66*380mm | D38: 个 | E38: B款 | F38: 包装辅料 | G38: 否 | H38: 1000
A39: BZ-023 | B39: 英文纸盒 | C39: 88*66*380mm | D39: 个 | E39: E款 | F39: 包装辅料 | G39: 否 | H39: 2000
A40: BZ-024 | B40: 保鲜膜 中文 | C40: 30CM*150M | D40: 箱 | E40: 保鲜膜 | F40: 包装辅料 | G40: 否 | H40: 100
...

Sheet BOM配方表
A1: 成品名称 | B1: 成品编码 | C1: 配件物料编码 | D1: 配件名称 | E1: 单件耗用数量 | F1: 备注
A2: A款收纳盒 | B2: CP-A | C2: CL-003 | D2: 磁铁 | E2: 2
A3: A款收纳盒 | B3: CP-A | C3: BZ-001 | D3: 子扣 | E3: 2
A4: A款收纳盒 | B4: CP-A | C4: BZ-002 | D4: PVC导轨条 | E4: 1
A5: A款收纳盒 | B5: CP-A | C5: CL-013 | D5: 硅胶吸盘 | E5: 4
A6: A款收纳盒 | B6: CP-A | C6: CL-015 | D6: 条形磁铁 | E6: 1
A7: A款收纳盒 | B7: CP-A | C7: BZ-034 | D7: A40外箱 | E7: 1
A8: B款收纳盒 | B8: CP-B | C8: CL-003 | D8: 磁铁 | E8: 1
A9: B款收纳盒 | B9: CP-B | C9: BZ-001 | D9: 子扣 | E9: 2
A10: B款收纳盒 | B10: CP-B | C10: CL-011 | D10: B款磁铁 | E10: 1
A11: B款收纳盒 | B11: CP-B | C11: CL-012 | D11: B款磁铁 | E11: 2
A12: B款收纳盒 | B12: CP-B | C12: BZ-022 | D12: B款英文纸盒 | E12: 1
A13: E款收纳盒 | B13: CP-E | C13: CL-007 | D13: EX磁铁 | E13: 1
... A31: 牙线盒 | B31: CP-Y | C31: BZ-003 | D31: 磨砂袋 | E31: 1

Sheet 入库记录表
A1: 入库单号 | B1: 入库日期 | C1: 物料编码 | D1: 货物名称 | E1: 规格材质 | F1: 单位 | G1: 入库数量 | H1: 供应商 | I1: 入库备注
A2: RK-0001 | B2: 46149 | C2: CL-001 | D2: =IF($C2="","",VLOOKUP($C2,物料档案表!$A:$D,2,FALSE)) | E2: =IF($C2="","",VLOOKUP($C2,物料档案表!$A:$D,3,FALSE)) | F2: =IF($C2="","",VLOOKUP($C2,物料档案表!$A:$D,4,FALSE)) | G2: 50000 | I2: [成品:牙线盒]
A3: RK-0002 | B3: 46149 | C3: CL-002 | D3: =IF($C3="","",VLOOKUP($C3,物料档案表!$A:$D,2,FALSE)) | E3: =IF($C3="","",VLOOKUP($C3,物料档案表!$A:$D,3,FALSE)) | F3: =IF($C3="","",VLOOKUP($C3,物料档案表!$A:$D,4,FALSE)) | G3: 100000 | I3: [成品:牙线盒]
A4: RK-0003 | B4: 46156 | C4: CL-003 | D4: =IF($C4="","",VLOOKUP($C4,物料档案表!$A:$D,2,FALSE)) | E4: =IF($C4="","",VLOOKUP($C4,物料档案表!$A:$D,3,FALSE)) | F4: =IF($C4="","",VLOOKUP($C4,物料档案表!$A:$D,4,FALSE)) | G4: 10000 | I4: [成品:A款 B款]
A5: RK-0004 | B5: 46156 | C5: CL-004 | D5: =IF($C5="","",VLOOKUP($C5,物料档案表!$A:$D,2,FALSE)) | E5: =IF($C5="","",VLOOKUP($C5,物料档案表!$A:$D,3,FALSE)) | F5: =IF($C5="","",VLOOKUP($C5,物料档案表!$A:$D,4,FALSE)) | G5: 10000 | I5: [成品:A款 B款]
A6: RK-0005 | B6: 46156 | C6: BZ-001 | D6: =IF($C6="","",VLOOKUP($C6,物料档案表!$A:$D,2,FALSE)) | E6: =IF($C6="","",VLOOKUP($C6,物料档案表!$A:$D,3,FALSE)) | F6: =IF($C6="","",VLOOKUP($C6,物料档案表!$A:$D,4,FALSE)) | G6: 5000 | I6: [成品:通用款]
A7: RK-0006 | B7: 46157 | C7: BZ-002 | D7: =IF($C7="","",VLOOKUP($C7,物料档案表!$A:$D,2,FALSE)) | E7: =IF($C7="","",VLOOKUP($C7,物料档案表!$A:$D,3,FALSE)) | F7: =IF($C7="","",VLOOKUP($C7,物料档案表!$A:$D,4,FALSE)) | G7: 15000 | I7: [成品:通用款] 1000根/箱 共15箱
A8: RK-0007 | B8: 46157 | C8: BZ-003 | D8: =IF($C8="","",VLOOKUP($C8,物料档案表!$A:$D,2,FALSE)) | E8: =IF($C8="","",VLOOKUP($C8,物料档案表!$A:$D,3,FALSE)) | F8: =IF($C8="","",VLOOKUP($C8,物料档案表!$A:$D,4,FALSE)) | G8: 20000 | I8: [成品:牙线盒]
A9: RK-0008 | B9: 46162 | C9: BZ-004 | D9: =IF($C9="","",VLOOKUP($C9,物料档案表!$A:$D,2,FALSE)) | E9: =IF($C9="","",VLOOKUP($C9,物料档案表!$A:$D,3,FALSE)) | F9: =IF($C9="","",VLOOKUP($C9,物料档案表!$A:$D,4,FALSE)) | G9: 3000 | I9: [成品:M金属款] 金属款
A10: RK-0009 | B10: 46162 | C10: CL-005 | D10: =IF($C10="","",VLOOKUP($C10,物料档案表!$A:$D,2,FALSE)) | E10: =IF($C10="","",VLOOKUP($C10,物料档案表!$A:$D,3,FALSE)) | F10: =IF($C10="","",VLOOKUP($C10,物料档案表!$A:$D,4,FALSE)) | G10: 10000 | I10: [成品:340铝管]
A11: RK-0010 | B11: 46165 | C11: CL-006 | D11: =IF($C11="","",VLOOKUP($C11,物料档案表!$A:$D,2,FALSE)) | E11: =IF($C11="","",VLOOKUP($C11,物料档案表!$A:$D,3,FALSE)) | F11: =IF($C11="","",VLOOKUP($C11,物料档案表!$A:$D,4,FALSE)) | G11: 3000 | I11: [成品:350铝轴]
A12: RK-0011 | B12: 46165 | C12: CL-007 | D12: =IF($C12="","",VLOOKUP($C12,物料档案表!$A:$D,2,FALSE)) | E12: =IF($C12="","",VLOOKUP($C12,物料档案表!$A:$D,3,FALSE)) | F12: =IF($C12="","",VLOOKUP($C12,物料档案表!$A:$D,4,FALSE)) | G12: 5000 | I12: [成品:E款]
A13: RK-0012 | B13: 46165 | C13: BZ-005 | D13: =IF($C13="","",VLOOKUP($C13,物料档案表!$A:$D,2,FALSE)) | E13: =IF($C13="","",VLOOKUP($C13,物料档案表!$A:$D,3,FALSE)) | F13: =IF($C13="","",VLOOKUP($C13,物料档案表!$A:$D,4,FALSE)) | G13: 10000 | I13: [成品:SN 收纳盒] 垃圾袋 收纳盒
... A97: RK-0096 | B97: 46239 | C97: BZ-001 | D97: =IF($C97="","",VLOOKUP($C97,物料档案表!$A:$D,2,FALSE)) | E97: =IF($C97="","",VLOOKUP($C97,物料档案表!$A:$D,3,FALSE)) | F97: =IF($C97="","",VLOOKUP($C97,物料档案表!$A:$D,4,FALSE)) | G97: 5000 | I97: [成品:E款 M款]

Sheet 出库领料记录表
A1: 出库单号 | B1: 出库日期 | C1: 领料类型 | D1: 成品编码 | E1: 生产数量 | F1: 物料编码 | G1: 货物名称 | H1: 规格材质 | I1: 单位 | J1: 出库数量 | K1: 出库方向 | L1: 领用人员 | M1: 出库备注
F2: =IF($D$2="","",IFERROR(IF(INDEX('BOM配方表'!$B$2:$B$200,MATCH($D$2,'BOM配方表'!$B$2:$B$200,0)+0)=$D$2,INDEX('BOM配方表'!$C$2:$C$200,MATCH($D$2,'BOM配方表'!$B$2:$B$200,0)+0),""),"")) | G2: =IF($F2="","",IFERROR(VLOOKUP($F2,物料档案表!$A:$D,2,FALSE),"")) | H2: =IF($F2="","",IFERROR(VLOOKUP($F2,物料档案表!$A:$D,3,FALSE),"")) | I2: =IF($F2="","",IFERROR(VLOOKUP($F2,物料档案表!$A:$D,4,FALSE),"")) | J2: =IF($F2="","",IFERROR(INDEX('BOM配方表'!$E$2:$E$200,MATCH($D$2,'BOM配方表'!$B$2:$B$200,0)+0)*$E$2,""))
F3: =IF($D$2="","",IFERROR(IF(INDEX('BOM配方表'!$B$2:$B$200,MATCH($D$2,'BOM配方表'!$B$2:$B$200,0)+1)=$D$2,INDEX('BOM配方表'!$C$2:$C$200,MATCH($D$2,'BOM配方表'!$B$2:$B$200,0)+1),""),"")) | G3: =IF($F3="","",IFERROR(VLOOKUP($F3,物料档案表!$A:$D,2,FALSE),"")) | H3: =IF($F3="","",IFERROR(VLOOKUP($F3,物料档案表!$A:$D,3,FALSE),"")) | I3: =IF($F3="","",IFERROR(VLOOKUP($F3,物料档案表!$A:$D,4,FALSE),"")) | J3: =IF($F3="","",IFERROR(INDEX('BOM配方表'!$E$2:$E$200,MATCH($D$2,'BOM配方表'!$B$2:$B$200,0)+1)*$E$2,""))
F4: =IF($D$2="","",IFERROR(IF(INDEX('BOM配方表'!$B$2:$B$200,MATCH($D$2,'BOM配方表'!$B$2:$B$200,0)+2)=$D$2,INDEX('BOM配方表'!$C$2:$C$200,MATCH($D$2,'BOM配方表'!$B$2:$B$200,0)+2),""),"")) | G4: =IF($F4="","",IFERROR(VLOOKUP($F4,物料档案表!$A:$D,2,FALSE),"")) | H4: =IF($F4="","",IFERROR(VLOOKUP($F4,物料档案表!$A:$D,3,FALSE),"")) | I4: =IF($F4="","",IFERROR(VLOOKUP($F4,物料档案表!$A:$D,4,FALSE),"")) | J4: =IF($F4="","",IFERROR(INDEX('BOM配方表'!$E$2:$E$200,MATCH($D$2,'BOM配方表'!$B$2:$B$200,0)+2)*$E$2,""))
F5: =IF($D$2="","",IFERROR(IF(INDEX('BOM配方表'!$B$2:$B$200,MATCH($D$2,'BOM配方表'!$B$2:$B$200,0)+3)=$D$2,INDEX('BOM配方表'!$C$2:$C$200,MATCH($D$2,'BOM配方表'!$B$2:$B$200,0)+3),""),"")) | G5: =IF($F5="","",IFERROR(VLOOKUP($F5,物料档案表!$A:$D,2,FALSE),"")) | H5: =IF($F5="","",IFERROR(VLOOKUP($F5,物料档案表!$A:$D,3,FALSE),"")) | I5: =IF($F5="","",IFERROR(VLOOKUP($F5,物料档案表!$A:$D,4,FALSE),"")) | J5: =IF($F5="","",IFERROR(INDEX('BOM配方表'!$E$2:$E$200,MATCH($D$2,'BOM配方表'!$B$2:$B$200,0)+3)*$E$2,""))
F6: =IF($D$2="","",IFERROR(IF(INDEX('BOM配方表'!$B$2:$B$200,MATCH($D$2,'BOM配方表'!$B$2:$B$200,0)+4)=$D$2,INDEX('BOM配方表'!$C$2:$C$200,MATCH($D$2,'BOM配方表'!$B$2:$B$200,0)+4),""),"")) | G6: =IF($F6="","",IFERROR(VLOOKUP($F6,物料档案表!$A:$D,2,FALSE),"")) | H6: =IF($F6="","",IFERROR(VLOOKUP($F6,物料档案表!$A:$D,3,FALSE),"")) | I6: =IF($F6="","",IFERROR(VLOOKUP($F6,物料档案表!$A:$D,4,FALSE),"")) | J6: =IF($F6="","",IFERROR(INDEX('BOM配方表'!$E$2:$E$200,MATCH($D$2,'BOM配方表'!$B$2:$B$200,0)+4)*$E$2,""))
F7: =IF($D$2="","",IFERROR(IF(INDEX('BOM配方表'!$B$2:$B$200,MATCH($D$2,'BOM配方表'!$B$2:$B$200,0)+5)=$D$2,INDEX('BOM配方表'!$C$2:$C$200,MATCH($D$2,'BOM配方表'!$B$2:$B$200,0)+5),""),"")) | G7: =IF($F7="","",IFERROR(VLOOKUP($F7,物料档案表!$A:$D,2,FALSE),"")) | H7: =IF($F7="","",IFERROR(VLOOKUP($F7,物料档案表!$A:$D,3,FALSE),"")) | I7: =IF($F7="","",IFERROR(VLOOKUP($F7,物料档案表!$A:$D,4,FALSE),"")) | J7: =IF($F7="","",IFERROR(INDEX('BOM配方表'!$E$2:$E$200,MATCH($D$2,'BOM配方表'!$B$2:$B$200,0)+5)*$E$2,""))
F8: =IF($D$2="","",IFERROR(IF(INDEX('BOM配方表'!$B$2:$B$200,MATCH($D$2,'BOM配方表'!$B$2:$B$200,0)+6)=$D$2,INDEX('BOM配方表'!$C$2:$C$200,MATCH($D$2,'BOM配方表'!$B$2:$B$200,0)+6),""),"")) | G8: =IF($F8="","",IFERROR(VLOOKUP($F8,物料档案表!$A:$D,2,FALSE),"")) | H8: =IF($F8="","",IFERROR(VLOOKUP($F8,物料档案表!$A:$D,3,FALSE),"")) | I8: =IF($F8="","",IFERROR(VLOOKUP($F8,物料档案表!$A:$D,4,FALSE),"")) | J8: =IF($F8="","",IFERROR(INDEX('BOM配方表'!$E$2:$E$200,MATCH($D$2,'BOM配方表'!$B$2:$B$200,0)+6)*$E$2,""))
F9: =IF($D$2="","",IFERROR(IF(INDEX('BOM配方表'!$B$2:$B$200,MATCH($D$2,'BOM配方表'!$B$2:$B$200,0)+7)=$D$2,INDEX('BOM配方表'!$C$2:$C$200,MATCH($D$2,'BOM配方表'!$B$2:$B$200,0)+7),""),"")) | G9: =IF($F9="","",IFERROR(VLOOKUP($F9,物料档案表!$A:$D,2,FALSE),"")) | H9: =IF($F9="","",IFERROR(VLOOKUP($F9,物料档案表!$A:$D,3,FALSE),"")) | I9: =IF($F9="","",IFERROR(VLOOKUP($F9,物料档案表!$A:$D,4,FALSE),"")) | J9: =IF($F9="","",IFERROR(INDEX('BOM配方表'!$E$2:$E$200,MATCH($D$2,'BOM配方表'!$B$2:$B$200,0)+7)*$E$2,""))
F10: =IF($D$2="","",IFERROR(IF(INDEX('BOM配方表'!$B$2:$B$200,MATCH($D$2,'BOM配方表'!$B$2:$B$200,0)+8)=$D$2,INDEX('BOM配方表'!$C$2:$C$200,MATCH($D$2,'BOM配方表'!$B$2:$B$200,0)+8),""),"")) | G10: =IF($F10="","",IFERROR(VLOOKUP($F10,物料档案表!$A:$D,2,FALSE),"")) | H10: =IF($F10="","",IFERROR(VLOOKUP($F10,物料档案表!$A:$D,3,FALSE),"")) | I10: =IF($F10="","",IFERROR(VLOOKUP($F10,物料档案表!$A:$D,4,FALSE),"")) | J10: =IF($F10="","",IFERROR(INDEX('BOM配方表'!$E$2:$E$200,MATCH($D$2,'BOM配方表'!$B$2:$B$200,0)+8)*$E$2,""))
F11: =IF($D$2="","",IFERROR(IF(INDEX('BOM配方表'!$B$2:$B$200,MATCH($D$2,'BOM配方表'!$B$2:$B$200,0)+9)=$D$2,INDEX('BOM配方表'!$C$2:$C$200,MATCH($D$2,'BOM配方表'!$B$2:$B$200,0)+9),""),"")) | G11: =IF($F11="","",IFERROR(VLOOKUP($F11,物料档案表!$A:$D,2,FALSE),"")) | H11: =IF($F11="","",IFERROR(VLOOKUP($F11,物料档案表!$A:$D,3,FALSE),"")) | I11: =IF($F11="","",IFERROR(VLOOKUP($F11,物料档案表!$A:$D,4,FALSE),"")) | J11: =IF($F11="","",IFERROR(INDEX('BOM配方表'!$E$2:$E$200,MATCH($D$2,'BOM配方表'!$B$2:$B$200,0)+9)*$E$2,""))
A102: 使用说明: 第2~11行为BOM批量生产领料区(D2填成品编码,E2填生产数量,自动带出配件); 单独领料请在12行起手动录入。

Sheet 实时库存余额表
A1: 物料编码 | B1: 货物名称 | C1: 规格材质 | D1: 单位 | E1: 适用成品 | F1: 物料大类 | G1: 是否通用 | H1: 期初库存 | I1: 本期总入库 | J1: 本期总出库 | K1: 当前剩余库存 | L1: 安全库存 | M1: 库存状态
A2: CL-001 | B2: 0.3拉簧 | D2: 个 | E2: 牙线盒 | F2: 原材料 | G2: 否 | H2: 0 | I2: =SUMIFS(入库记录表!$G:$G,入库记录表!$C:$C,$A2) | J2: =SUMIFS(出库领料记录表!$J:$J,出库领料记录表!$F:$F,$A2) | K2: =H2+I2-J2 | L2: 10000 | M2: =IF(K2<=L2,"库存不足","正常")
A3: CL-002 | B3: 0.2压簧 | D3: 个 | E3: 牙线盒 | F3: 原材料 | G3: 否 | H3: 0 | I3: =SUMIFS(入库记录表!$G:$G,入库记录表!$C:$C,$A3) | J3: =SUMIFS(出库领料记录表!$J:$J,出库领料记录表!$F:$F,$A3) | K3: =H3+I3-J3 | L3: 10000 | M3: =IF(K3<=L3,"库存不足","正常")
A4: CL-003 | B4: 磁铁 | C4: D6*2 | D4: 片 | E4: A款,B款 | F4: 原材料 | G4: 是 | H4: 0 | I4: =SUMIFS(入库记录表!$G:$G,入库记录表!$C:$C,$A4) | J4: =SUMIFS(出库领料记录表!$J:$J,出库领料记录表!$F:$F,$A4) | K4: =H4+I4-J4 | L4: 20000 | M4: =IF(K4<=L4,"库存不足","正常")
A5: CL-004 | B5: 磁铁 | C5: D6*3 | D5: 片 | E5: A款,B款 | F5: 原材料 | G5: 是 | H5: 0 | I5: =SUMIFS(入库记录表!$G:$G,入库记录表!$C:$C,$A5) | J5: =SUMIFS(出库领料记录表!$J:$J,出库领料记录表!$F:$F,$A5) | K5: =H5+I5-J5 | L5: 10000 | M5: =IF(K5<=L5,"库存不足","正常")
A6: CL-005 | B6: 201 中轴 | C6: 10*0.4*340 | D6: pcs | E6: 340铝管,350铝轴 | F6: 原材料 | G6: 是 | H6: 0 | I6: =SUMIFS(入库记录表!$G:$G,入库记录表!$C:$C,$A6) | J6: =SUMIFS(出库领料记录表!$J:$J,出库领料记录表!$F:$F,$A6) | K6: =H6+I6-J6 | L6: 2000 | M6: =IF(K6<=L6,"库存不足","正常")
A7: CL-006 | B7: 201 | C7: 10*0.4*350 | D7: pcs | E7: 350铝轴 | F7: 原材料 | G7: 否 | H7: 0 | I7: =SUMIFS(入库记录表!$G:$G,入库记录表!$C:$C,$A7) | J7: =SUMIFS(出库领料记录表!$J:$J,出库领料记录表!$F:$F,$A7) | K7: =H7+I7-J7 | L7: 2000 | M7: =IF(K7<=L7,"库存不足","正常")
A8: CL-007 | B8: EX 磁铁 | C8: 250*55*1.5 | D8: pcs | E8: E款 | F8: 原材料 | G8: 否 | H8: 0 | I8: =SUMIFS(入库记录表!$G:$G,入库记录表!$C:$C,$A8) | J8: =SUMIFS(出库领料记录表!$J:$J,出库领料记录表!$F:$F,$A8) | K8: =H8+I8-J8 | L8: 1000 | M8: =IF(K8<=L8,"库存不足","正常")
A9: CL-008 | B9: M款 磁铁 | C9: 249*60*2.0mm | D9: pcs | E9: M金属款 | F9: 原材料 | G9: 否 | H9: 0 | I9: =SUMIFS(入库记录表!$G:$G,入库记录表!$C:$C,$A9) | J9: =SUMIFS(出库领料记录表!$J:$J,出库领料记录表!$F:$F,$A9) | K9: =H9+I9-J9 | L9: 500 | M9: =IF(K9<=L9,"库存不足","正常")
A10: CL-009 | B10: 不锈钢外壳 | C10: 304 | D10: pcs | E10: M金属款 | F10: 原材料 | G10: 否 | H10: 0 | I10: =SUMIFS(入库记录表!$G:$G,入库记录表!$C:$C,$A10) | J10: =SUMIFS(出库领料记录表!$J:$J,出库领料记录表!$F:$F,$A10) | K10: =H10+I10-J10 | L10: 500 | M10: =IF(K10<=L10,"库存不足","正常")
A11: CL-010 | B11: SN 磁铁 | C11: 165*58*1.5mm | D11: pcs | E11: SN收纳盒 | F11: 原材料 | G11: 否 | H11: 0 | I11: =SUMIFS(入库记录表!$G:$G,入库记录表!$C:$C,$A11) | J11: =SUMIFS(出库领料记录表!$J:$J,出库领料记录表!$F:$F,$A11) | K11: =H11+I11-J11 | L11: 500 | M11: =IF(K11<=L11,"库存不足","正常")
A12: CL-011 | B12: B款 磁铁 | C12: 159*28*1.5mm | D12: pcs | E12: B款 | F12: 原材料 | G12: 否 | H12: 0 | I12: =SUMIFS(入库记录表!$G:$G,入库记录表!$C:$C,$A12) | J12: =SUMIFS(出库领料记录表!$J:$J,出库领料记录表!$F:$F,$A12) | K12: =H12+I12-J12 | L12: 1000 | M12: =IF(K12<=L12,"库存不足","正常")
A13: CL-012 | B13: B款 磁铁 | C13: 54.6*28*1.5mm | D13: pcs | E13: B款 | F13: 原材料 | G13: 否 | H13: 0 | I13: =SUMIFS(入库记录表!$G:$G,入库记录表!$C:$C,$A13) | J13: =SUMIFS(出库领料记录表!$J:$J,出库领料记录表!$F:$F,$A13) | K13: =H13+I13-J13 | L13: 1000 | M13: =IF(K13<=L13,"库存不足","正常")
A14: CL-013 | B14: 硅胶吸盘 | D14: 套 | E14: A款 | F14: 原材料 | G14: 否 | H14: 0 | I14: =SUMIFS(入库记录表!$G:$G,入库记录表!$C:$C,$A14) | J14: =SUMIFS(出库领料记录表!$J:$J,出库领料记录表!$F:$F,$A14) | K14: =H14+I14-J14 | L14: 1000 | M14: =IF(K14<=L14,"库存不足","正常")
A15: CL-014 | B15: CE100款 磁铁 | C15: 265*58.5*1.5mm | D15: pcs | E15: CE100款 | F15: 原材料 | G15: 否 | H15: 0 | I15: =SUMIFS(入库记录表!$G:$G,入库记录表!$C:$C,$A15) | J15: =SUMIFS(出库领料记录表!$J:$J,出库领料记录表!$F:$F,$A15) | K15: =H15+I15-J15 | L15: 200 | M15: =IF(K15<=L15,"库存不足","正常")
A16: CL-015 | B16: 条形磁铁 | C16: 323*24*1.5 | E16: A款 | F16: 原材料 | G16: 否 | H16: 0 | I16: =SUMIFS(入库记录表!$G:$G,入库记录表!$C:$C,$A16) | J16: =SUMIFS(出库领料记录表!$J:$J,出库领料记录表!$F:$F,$A16) | K16: =H16+I16-J16 | L16: 500 | M16: =IF(K16<=L16,"库存不足","正常")
A17: BZ-001 | B17: 子扣 | C17: 6*6CM | D17: 包 | E17: 通用,E款,M款 | F17: 包装辅料 | G17: 是 | H17: 0 | I17: =SUMIFS(入库记录表!$G:$G,入库记录表!$C:$C,$A17) | J17: =SUMIFS(出库领料记录表!$J:$J,出库领料记录表!$F:$F,$A17) | K17: =H17+I17-J17 | L17: 10000 | M17: =IF(K17<=L17,"库存不足","正常")
A18: BZ-002 | B18: PVC导轨条 | C18: 330MM | D18: 根 | E18: 通用 | F18: 包装辅料 | G18: 否 | H18: 0 | I18: =SUMIFS(入库记录表!$G:$G,入库记录表!$C:$C,$A18) | J18: =SUMIFS(出库领料记录表!$J:$J,出库领料记录表!$F:$F,$A18) | K18: =H18+I18-J18 | L18: 10000 | M18: =IF(K18<=L18,"库存不足","正常")
A19: BZ-003 | B19: 磨砂袋 | C19: 牙线盒 | D19: 个 | E19: 牙线盒 | F19: 包装辅料 | G19: 否 | H19: 0 | I19: =SUMIFS(入库记录表!$G:$G,入库记录表!$C:$C,$A19) | J19: =SUMIFS(出库领料记录表!$J:$J,出库领料记录表!$F:$F,$A19) | K19: =H19+I19-J19 | L19: 5000 | M19: =IF(K19<=L19,"库存不足","正常")
A20: BZ-004 | B20: 气泡袋 | C20: 15*43CM | D20: 个 | E20: M金属款 | F20: 包装辅料 | G20: 否 | H20: 0 | I20: =SUMIFS(入库记录表!$G:$G,入库记录表!$C:$C,$A20) | J20: =SUMIFS(出库领料记录表!$J:$J,出库领料记录表!$F:$F,$A20) | K20: =H20+I20-J20 | L20: 2000 | M20: =IF(K20<=L20,"库存不足","正常")
A21: BZ-005 | B21: SN 磨砂袋 | C21: 14.5*29cm | D21: CPE | E21: SN收纳盒 | F21: 包装辅料 | G21: 否 | H21: 0 | I21: =SUMIFS(入库记录表!$G:$G,入库记录表!$C:$C,$A21) | J21: =SUMIFS(出库领料记录表!$J:$J,出库领料记录表!$F:$F,$A21) | K21: =H21+I21-J21 | L21: 1000 | M21: =IF(K21<=L21,"库存不足","正常")
A22: BZ-006 | B22: EX 磨砂袋 | C22: 14.5*49cm | D22: CPE | E22: E款,B款 | F22: 包装辅料 | G22: 是 | H22: 0 | I22: =SUMIFS(入库记录表!$G:$G,入库记录表!$C:$C,$A22) | J22: =SUMIFS(出库领料记录表!$J:$J,出库领料记录表!$F:$F,$A22) | K22: =H22+I22-J22 | L22: 1000 | M22: =IF(K22<=L22,"库存不足","正常")
A23: BZ-007 | B23: E款 中文 | C23: 88*66*380mm | D23: 个 | E23: E款 | F23: 包装辅料 | G23: 否 | H23: 0 | I23: =SUMIFS(入库记录表!$G:$G,入库记录表!$C:$C,$A23) | J23: =SUMIFS(出库领料记录表!$J:$J,出库领料记录表!$F:$F,$A23) | K23: =H23+I23-J23 | L23: 2000 | M23: =IF(K23<=L23,"库存不足","正常")
A24: BZ-008 | B24: E款 英文 | C24: 88*66*380mm | D24: 个 | E24: E款 | F24: 包装辅料 | G24: 否 | H24: 0 | I24: =SUMIFS(入库记录表!$G:$G,入库记录表!$C:$C,$A24) | J24: =SUMIFS(出库领料记录表!$J:$J,出库领料记录表!$F:$F,$A24) | K24: =H24+I24-J24 | L24: 2000 | M24: =IF(K24<=L24,"库存不足","正常")
A25: BZ-009 | B25: CE32 外箱 | C25: 560*385*395mm | D25: 个 | E25: E款,B款 | F25: 包装辅料 | G25: 是 | H25: 0 | I25: =SUMIFS(入库记录表!$G:$G,入库记录表!$C:$C,$A25) | J25: =SUMIFS(出库领料记录表!$J:$J,出库领料记录表!$F:$F,$A25) | K25: =H25+I25-J25 | L25: 500 | M25: =IF(K25<=L25,"库存不足","正常")
A26: BZ-010 | B26: H款快递盒 | C26: 222*105*410mm | D26: 个 | E26: 打包盒 | F26: 包装辅料 | G26: 否 | H26: 0 | I26: =SUMIFS(入库记录表!$G:$G,入库记录表!$C:$C,$A26) | J26: =SUMIFS(出库领料记录表!$J:$J,出库领料记录表!$F:$F,$A26) | K26: =H26+I26-J26 | L26: 1000 | M26: =IF(K26<=L26,"库存不足","正常")
A27: BZ-011 | B27: M+200M 纸盒 | C27: 124*100*395mm | D27: 个 | E27: 打包盒 | F27: 包装辅料 | G27: 否 | H27: 0 | I27: =SUMIFS(入库记录表!$G:$G,入库记录表!$C:$C,$A27) | J27: =SUMIFS(出库领料记录表!$J:$J,出库领料记录表!$F:$F,$A27) | K27: =H27+I27-J27 | L27: 1000 | M27: =IF(K27<=L27,"库存不足","正常")
A28: BZ-012 | B28: M款彩盒-中文 | D28: 个 | E28: M金属款 | F28: 包装辅料 | G28: 否 | H28: 0 | I28: =SUMIFS(入库记录表!$G:$G,入库记录表!$C:$C,$A28) | J28: =SUMIFS(出库领料记录表!$J:$J,出库领料记录表!$F:$F,$A28) | K28: =H28+I28-J28 | L28: 500 | M28: =IF(K28<=L28,"库存不足","正常")
A29: BZ-013 | B29: M款彩盒-英文 | D29: 个 | E29: M金属款 | F29: 包装辅料 | G29: 否 | H29: 0 | I29: =SUMIFS(入库记录表!$G:$G,入库记录表!$C:$C,$A29) | J29: =SUMIFS(出库领料记录表!$J:$J,出库领料记录表!$F:$F,$A29) | K29: =H29+I29-J29 | L29: 500 | M29: =IF(K29<=L29,"库存不足","正常")
A30: BZ-014 | B30: 子扣 | C30: 75C60*60方格 | D30: 片 | E30: SA收纳盒 | F30: 包装辅料 | G30: 否 | H30: 0 | I30: =SUMIFS(入库记录表!$G:$G,入库记录表!$C:$C,$A30) | J30: =SUMIFS(出库领料记录表!$J:$J,出库领料记录表!$F:$F,$A30) | K30: =H30+I30-J30 | L30: 1000 | M30: =IF(K30<=L30,"库存不足","正常")
A31: BZ-015 | B31: 子扣 | C31: 75C60*60方格（25mm) | D31: 包 | E31: SN收纳盒 | F31: 包装辅料 | G31: 否 | H31: 0 | I31: =SUMIFS(入库记录表!$G:$G,入库记录表!$C:$C,$A31) | J31: =SUMIFS(出库领料记录表!$J:$J,出库领料记录表!$F:$F,$A31) | K31: =H31+I31-J31 | L31: 1000 | M31: =IF(K31<=L31,"库存不足","正常")
A32: BZ-016 | B32: 保鲜膜 中文 | C32: 30CM*100M | D32: 箱 | E32: 保鲜膜 | F32: 包装辅料 | G32: 否 | H32: 0 | I32: =SUMIFS(入库记录表!$G:$G,入库记录表!$C:$C,$A32) | J32: =SUMIFS(出库领料记录表!$J:$J,出库领料记录表!$F:$F,$A32) | K32: =H32+I32-J32 | L32: 100 | M32: =IF(K32<=L32,"库存不足","正常")
A33: BZ-017 | B33: 保鲜膜 中文 | C33: 30CM*50M | D33: 箱 | E33: 保鲜膜 | F33: 包装辅料 | G33: 否 | H33: 0 | I33: =SUMIFS(入库记录表!$G:$G,入库记录表!$C:$C,$A33) | J33: =SUMIFS(出库领料记录表!$J:$J,出库领料记录表!$F:$F,$A33) | K33: =H33+I33-J33 | L33: 100 | M33: =IF(K33<=L33,"库存不足","正常")
A34: BZ-018 | B34: SA 磨砂袋 | C34: 220*290 | D34: CPE | E34: SA收纳盒 | F34: 包装辅料 | G34: 否 | H34: 0 | I34: =SUMIFS(入库记录表!$G:$G,入库记录表!$C:$C,$A34) | J34: =SUMIFS(出库领料记录表!$J:$J,出库领料记录表!$F:$F,$A34) | K34: =H34+I34-J34 | L34: 500 | M34: =IF(K34<=L34,"库存不足","正常")
A35: BZ-019 | B35: 纸箱12 | C35: 390*100*82mm | D35: 个 | E35: 打包盒 | F35: 包装辅料 | G35: 否 | H35: 0 | I35: =SUMIFS(入库记录表!$G:$G,入库记录表!$C:$C,$A35) | J35: =SUMIFS(出库领料记录表!$J:$J,出库领料记录表!$F:$F,$A35) | K35: =H35+I35-J35 | L35: 500 | M35: =IF(K35<=L35,"库存不足","正常")
A36: BZ-020 | B36: E100 说明书 | D36: 个 | E36: E款 | F36: 包装辅料 | G36: 否 | H36: 0 | I36: =SUMIFS(入库记录表!$G:$G,入库记录表!$C:$C,$A36) | J36: =SUMIFS(出库领料记录表!$J:$J,出库领料记录表!$F:$F,$A36) | K36: =H36+I36-J36 | L36: 2000 | M36: =IF(K36<=L36,"库存不足","正常")
A37: BZ-021 | B37: M20 外箱 | C37: 400*380*410 | D37: 个 | E37: M金属款 | F37: 包装辅料 | G37: 否 | H37: 0 | I37: =SUMIFS(入库记录表!$G:$G,入库记录表!$C:$C,$A37) | J37: =SUMIFS(出库领料记录表!$J:$J,出库领料记录表!$F:$F,$A37) | K37: =H37+I37-J37 | L37: 300 | M37: =IF(K37<=L37,"库存不足","正常")
A38: BZ-022 | B38: B款 英文纸盒 | C38: 88*66*380mm | D38: 个 | E38: B款 | F38: 包装辅料 | G38: 否 | H38: 0 | I38: =SUMIFS(入库记录表!$G:$G,入库记录表!$C:$C,$A38) | J38: =SUMIFS(出库领料记录表!$J:$J,出库领料记录表!$F:$F,$A38) | K38: =H38+I38-J38 | L38: 1000 | M38: =IF(K38<=L38,"库存不足","正常")
A39: BZ-023 | B39: 英文纸盒 | C39: 88*66*380mm | D39: 个 | E39: E款 | F39: 包装辅料 | G39: 否 | H39: 0 | I39: =SUMIFS(入库记录表!$G:$G,入库记录表!$C:$C,$A39) | J39: =SUMIFS(出库领料记录表!$J:$J,出库领料记录表!$F:$F,$A39) | K39: =H39+I39-J39 | L39: 2000 | M39: =IF(K39<=L39,"库存不足","正常")
A40: BZ-024 | B40: 保鲜膜 中文 | C40: 30CM*150M | D40: 箱 | E40: 保鲜膜 | F40: 包装辅料 | G40: 否 | H40: 0 | I40: =SUMIFS(入库记录表!$G:$G,入库记录表!$C:$C,$A40) | J40: =SUMIFS(出库领料记录表!$J:$J,出库领料记录表!$F:$F,$A40) | K40: =H40+I40-J40 | L40: 100 | M40: =IF(K40<=L40,"库存不足","正常")
...
